Workbook

Sheet Итог
A1: Как считается
A2: target — верный slug из ручной разметки (Label Studio → data/labels/real-photos.json).
A3: top-1…top-5 — выдача на том же фото. Ранг target = MATCH(target; top-1:top-5).
A4: Верно top-1 = target на 1-м месте; верно top-5 = target в первой пятёрке. Фото без target (нет в каталоге, исключено) не считаются.
A5: VLM (Qwen3-VL-4B) переставляет первые 5 кандидатов картинки/OCR, поэтому top-5 у VLM-прогонов тот же, что у базы, а top-1 — выбор VLM. Пересобрать таблицу: python -m eval_runner.excel.
A7: Набор | B7: Конфигурация | C7: Фото | D7: Верно top-1 | E7: top-1 | F7: Верно top-5 | G7: top-5
A8: уверенно | B8: Без OCR | C8: =COUNTIFS('Без OCR'!$B$2:$B$101,"уверенно") | D8: =COUNTIFS('Без OCR'!$B$2:$B$101,"уверенно",'Без OCR'!$L$2:$L$101,1) | E8: =IF(C8=0,0,D8/C8) | F8: =COUNTIFS('Без OCR'!$B$2:$B$101,"уверенно",'Без OCR'!$M$2:$M$101,1) | G8: =IF(C8=0,0,F8/C8)
A9: уверенно | B9: С OCR | C9: =COUNTIFS('С OCR'!$B$2:$B$101,"уверенно") | D9: =COUNTIFS('С OCR'!$B$2:$B$101,"уверенно",'С OCR'!$L$2:$L$101,1) | E9: =IF(C9=0,0,D9/C9) | F9: =COUNTIFS('С OCR'!$B$2:$B$101,"уверенно",'С OCR'!$M$2:$M$101,1) | G9: =IF(C9=0,0,F9/C9)
A10: уверенно | B10: VLM текст | C10: =COUNTIFS('VLM текст'!$B$2:$B$101,"уверенно") | D10: =COUNTIFS('VLM текст'!$B$2:$B$101,"уверенно",'VLM текст'!$L$2:$L$101,1) | E10: =IF(C10=0,0,D10/C10) | F10: =COUNTIFS('VLM текст'!$B$2:$B$101,"уверенно",'VLM текст'!$M$2:$M$101,1) | G10: =IF(C10=0,0,F10/C10)
A11: уверенно | B11: VLM текст+фото | C11: =COUNTIFS('VLM текст+фото'!$B$2:$B$101,"уверенно") | D11: =COUNTIFS('VLM текст+фото'!$B$2:$B$101,"уверенно",'VLM текст+фото'!$L$2:$L$101,1) | E11: =IF(C11=0,0,D11/C11) | F11: =COUNTIFS('VLM текст+фото'!$B$2:$B$101,"уверенно",'VLM текст+фото'!$M$2:$M$101,1) | G11: =IF(C11=0,0,F11/C11)
A12: уверенно | B12: VLM текст+фото, малые | C12: =COUNTIFS('VLM текст+фото, малые'!$B$2:$B$101,"уверенно") | D12: =COUNTIFS('VLM текст+фото, малые'!$B$2:$B$101,"уверенно",'VLM текст+фото, малые'!$L$2:$L$101,1) | E12: =IF(C12=0,0,D12/C12) | F12: =COUNTIFS('VLM текст+фото, малые'!$B$2:$B$101,"уверенно",'VLM текст+фото, малые'!$M$2:$M$101,1) | G12: =IF(C12=0,0,F12/C12)
A13: уверенно | B13: VLM без OCR | C13: =COUNTIFS('VLM без OCR'!$B$2:$B$101,"уверенно") | D13: =COUNTIFS('VLM без OCR'!$B$2:$B$101,"уверенно",'VLM без OCR'!$L$2:$L$101,1) | E13: =IF(C13=0,0,D13/C13) | F13: =COUNTIFS('VLM без OCR'!$B$2:$B$101,"уверенно",'VLM без OCR'!$M$2:$M$101,1) | G13: =IF(C13=0,0,F13/C13)
A14: уверенно | B14: VLM без OCR, малые | C14: =COUNTIFS('VLM без OCR, малые'!$B$2:$B$101,"уверенно") | D14: =COUNTIFS('VLM без OCR, малые'!$B$2:$B$101,"уверенно",'VLM без OCR, малые'!$L$2:$L$101,1) | E14: =IF(C14=0,0,D14/C14) | F14: =COUNTIFS('VLM без OCR, малые'!$B$2:$B$101,"уверенно",'VLM без OCR, малые'!$M$2:$M$101,1) | G14: =IF(C14=0,0,F14/C14)
A15: уверенно | B15: Сервис VLM | C15: =COUNTIFS('Сервис VLM'!$B$2:$B$101,"уверенно") | D15: =COUNTIFS('Сервис VLM'!$B$2:$B$101,"уверенно",'Сервис VLM'!$L$2:$L$101,1) | E15: =IF(C15=0,0,D15/C15) | F15: =COUNTIFS('Сервис VLM'!$B$2:$B$101,"уверенно",'Сервис VLM'!$M$2:$M$101,1) | G15: =IF(C15=0,0,F15/C15)
A16: уверенно + не уверен | B16: Без OCR | C16: =COUNTIFS('Без OCR'!$B$2:$B$101,"уверенно")+COUNTIFS('Без OCR'!$B$2:$B$101,"не уверен") | D16: =COUNTIFS('Без OCR'!$B$2:$B$101,"уверенно",'Без OCR'!$L$2:$L$101,1)+COUNTIFS('Без OCR'!$B$2:$B$101,"не уверен",'Без OCR'!$L$2:$L$101,1) | E16: =IF(C16=0,0,D16/C16) | F16: =COUNTIFS('Без OCR'!$B$2:$B$101,"уверенно",'Без OCR'!$M$2:$M$101,1)+COUNTIFS('Без OCR'!$B$2:$B$101,"не уверен",'Без OCR'!$M$2:$M$101,1) | G16: =IF(C16=0,0,F16/C16)
A17: уверенно + не уверен | B17: С OCR | C17: =COUNTIFS('С OCR'!$B$2:$B$101,"уверенно")+COUNTIFS('С OCR'!$B$2:$B$101,"не уверен") | D17: =COUNTIFS('С OCR'!$B$2:$B$101,"уверенно",'С OCR'!$L$2:$L$101,1)+COUNTIFS('С OCR'!$B$2:$B$101,"не уверен",'С OCR'!$L$2:$L$101,1) | E17: =IF(C17=0,0,D17/C17) | F17: =COUNTIFS('С OCR'!$B$2:$B$101,"уверенно",'С OCR'!$M$2:$M$101,1)+COUNTIFS('С OCR'!$B$2:$B$101,"не уверен",'С OCR'!$M$2:$M$101,1) | G17: =IF(C17=0,0,F17/C17)
A18: уверенно + не уверен | B18: VLM текст | C18: =COUNTIFS('VLM текст'!$B$2:$B$101,"уверенно")+COUNTIFS('VLM текст'!$B$2:$B$101,"не уверен") | D18: =COUNTIFS('VLM текст'!$B$2:$B$101,"уверенно",'VLM текст'!$L$2:$L$101,1)+COUNTIFS('VLM текст'!$B$2:$B$101,"не уверен",'VLM текст'!$L$2:$L$101,1) | E18: =IF(C18=0,0,D18/C18) | F18: =COUNTIFS('VLM текст'!$B$2:$B$101,"уверенно",'VLM текст'!$M$2:$M$101,1)+COUNTIFS('VLM текст'!$B$2:$B$101,"не уверен",'VLM текст'!$M$2:$M$101,1) | G18: =IF(C18=0,0,F18/C18)
A19: уверенно + не уверен | B19: VLM текст+фото | C19: =COUNTIFS('VLM текст+фото'!$B$2:$B$101,"уверенно")+COUNTIFS('VLM текст+фото'!$B$2:$B$101,"не уверен") | D19: =COUNTIFS('VLM текст+фото'!$B$2:$B$101,"уверенно",'VLM текст+фото'!$L$2:$L$101,1)+COUNTIFS('VLM текст+фото'!$B$2:$B$101,"не уверен",'VLM текст+фото'!$L$2:$L$101,1) | E19: =IF(C19=0,0,D19/C19) | F19: =COUNTIFS('VLM текст+фото'!$B$2:$B$101,"уверенно",'VLM текст+фото'!$M$2:$M$101,1)+COUNTIFS('VLM текст+фото'!$B$2:$B$101,"не уверен",'VLM текст+фото'!$M$2:$M$101,1) | G19: =IF(C19=0,0,F19/C19)
A20: уверенно + не уверен | B20: VLM текст+фото, малые | C20: =COUNTIFS('VLM текст+фото, малые'!$B$2:$B$101,"уверенно")+COUNTIFS('VLM текст+фото, малые'!$B$2:$B$101,"не уверен") | D20: =COUNTIFS('VLM текст+фото, малые'!$B$2:$B$101,"уверенно",'VLM текст+фото, малые'!$L$2:$L$101,1)+COUNTIFS('VLM текст+фото, малые'!$B$2:$B$101,"не уверен",'VLM текст+фото, малые'!$L$2:$L$101,1) | E20: =IF(C20=0,0,D20/C20) | F20: =COUNTIFS('VLM текст+фото, малые'!$B$2:$B$101,"уверенно",'VLM текст+фото, малые'!$M$2:$M$101,1)+COUNTIFS('VLM текст+фото, малые'!$B$2:$B$101,"не уверен",'VLM текст+фото, малые'!$M$2:$M$101,1) | G20: =IF(C20=0,0,F20/C20)
A21: уверенно + не уверен | B21: VLM без OCR | C21: =COUNTIFS('VLM без OCR'!$B$2:$B$101,"уверенно")+COUNTIFS('VLM без OCR'!$B$2:$B$101,"не уверен") | D21: =COUNTIFS('VLM без OCR'!$B$2:$B$101,"уверенно",'VLM без OCR'!$L$2:$L$101,1)+COUNTIFS('VLM без OCR'!$B$2:$B$101,"не уверен",'VLM без OCR'!$L$2:$L$101,1) | E21: =IF(C21=0,0,D21/C21) | F21: =COUNTIFS('VLM без OCR'!$B$2:$B$101,"уверенно",'VLM без OCR'!$M$2:$M$101,1)+COUNTIFS('VLM без OCR'!$B$2:$B$101,"не уверен",'VLM без OCR'!$M$2:$M$101,1) | G21: =IF(C21=0,0,F21/C21)
A22: уверенно + не уверен | B22: VLM без OCR, малые | C22: =COUNTIFS('VLM без OCR, малые'!$B$2:$B$101,"уверенно")+COUNTIFS('VLM без OCR, малые'!$B$2:$B$101,"не уверен") | D22: =COUNTIFS('VLM без OCR, малые'!$B$2:$B$101,"уверенно",'VLM без OCR, малые'!$L$2:$L$101,1)+COUNTIFS('VLM без OCR, малые'!$B$2:$B$101,"не уверен",'VLM без OCR, малые'!$L$2:$L$101,1) | E22: =IF(C22=0,0,D22/C22) | F22: =COUNTIFS('VLM без OCR, малые'!$B$2:$B$101,"уверенно",'VLM без OCR, малые'!$M$2:$M$101,1)+COUNTIFS('VLM без OCR, малые'!$B$2:$B$101,"не уверен",'VLM без OCR, малые'!$M$2:$M$101,1) | G22: =IF(C22=0,0,F22/C22)
A23: уверенно + не уверен | B23: Сервис VLM | C23: =COUNTIFS('Сервис VLM'!$B$2:$B$101,"уверенно")+COUNTIFS('Сервис VLM'!$B$2:$B$101,"не уверен") | D23: =COUNTIFS('Сервис VLM'!$B$2:$B$101,"уверенно",'Сервис VLM'!$L$2:$L$101,1)+COUNTIFS('Сервис VLM'!$B$2:$B$101,"не уверен",'Сервис VLM'!$L$2:$L$101,1) | E23: =IF(C23=0,0,D23/C23) | F23: =COUNTIFS('Сервис VLM'!$B$2:$B$101,"уверенно",'Сервис VLM'!$M$2:$M$101,1)+COUNTIFS('Сервис VLM'!$B$2:$B$101,"не уверен",'Сервис VLM'!$M$2:$M$101,1) | G23: =IF(C23=0,0,F23/C23)
A25: Фото «нет в каталоге» | C25: =COUNTIFS('С OCR'!$B$2:$B$101,"нет в каталоге")
A26: Исключено (две бутылки в кадре) | C26: =COUNTIFS('С OCR'!$B$2:$B$101,"исключено")
A28: Конфигурация | B28: OCR | C28: Вход VLM | D28: Картинки VLM (фото / эталон) | E28: VLM, медиана мс | F28: VLM, p95 мс | G28: Ответ, p95 мс | H28: Отказ «нет в каталоге» (P>0,5) | I28: Ложные отказы | J28: Файл | K28: Примечание
A29: Без OCR | B29: нет | C29: — | D29: — | E29: — | F29: — | G29: 416 | H29: — | I29: — | J29: data/reports/results.jsonl
A30: С OCR | B30: да | C30: — | D30: — | E30: — | F30: — | G30: 835 | H30: — | I30: — | J30: data/reports/ocr/results.jsonl
A31: VLM текст | B31: да | C31: текст карточек | D31: 1 Мп | E31: 556 | F31: 595 | G31: 1427 | H31: 6 из 33 | I31: 0 из 66 | J31: data/reports/vlm-text/results.jsonl
A32: VLM текст+фото | B32: да | C32: текст + эталонные фото | D32: 1 Мп / 256k | E32: 1095 | F32: 1832 | G32: 2417 | H32: 6 из 33 | I32: 1 из 66 | J32: data/reports/vlm-images/results.jsonl
A33: VLM текст+фото, малые | B33: да | C33: текст + эталонные фото | D33: 512k / 128k | E33: 745 | F33: 1369 | G33: 1953 | H33: 5 из 33 | I33: 0 из 66 | J33: data/reports/vlm-images-small/results.jsonl
A34: VLM без OCR | B34: нет | C34: текст + эталонные фото | D34: 1 Мп / 256k | E34: 1065 | F34: 1693 | G34: 2039 | H34: 7 из 33 | I34: 1 из 66 | J34: data/reports/vlm-images-noocr/results.jsonl
A35: VLM без OCR, малые | B35: нет | C35: текст + эталонные фото | D35: 512k / 128k | E35: 740 | F35: 1191 | G35: 1549 | H35: 6 из 33 | I35: 0 из 66 | J35: data/reports/vlm-images-noocr-small/results.jsonl | K35: лучший вариант
A36: Сервис VLM | B36: нет | C36: текст + эталонные фото | D36: 512k / 128k | E36: 726 | F36: 1199 | G36: 1682 | H36: 6 из 33 | I36: 0 из 66 | J36: data/reports/service-vlm/results.jsonl | K36: тот же вариант, встроенный в сервис: WINE_VLM_ENABLED=1, WINE_OCR_ENABLED=0
A38: «Ответ, p95» у офлайн-прогонов — время сервиса до VLM плюс сам VLM; у «Сервис VLM» — замер клиентом, как у скрипта организатора. SLA — 3 с.

Sheet Без OCR
A1: Фото | B1: Статус разметки | C1: target | D1: target: вино | E1: Комментарий разметчика | F1: top-1 | G1: top-2 | H1: top-3 | I1: top-4 | J1: top-5 | K1: Ранг target | L1: Верно top-1 | M1: Верно top-5 | N1: top-1: вино | O1: top-2: вино | P1: top-3: вино | Q1: top-4: вино | R1: top-5: вино
A2: 1.73_06-09-2026_14-54-06.webp | B2: не уверен | C2: fanagoriya-rose-kaberne-fran-rozovoe-suhoe-13 | D2: Rose. Каберне Фран — Фанагория — Розовое сухое | E2: договоримся так, после __ я буду писать свои комментарии. этого вина нет в наборе, но я не уверен | F2: rozovoe-polusladkoe | G2: fanagoriya-beloe-polusladkoe | H2: vinodelnya-pokrovskaya-marinka-marinovskiy-rozovoe-suhoe-123 | I2: zolotaya-balka-pink-sira-rozovoe-suhoe-13 | J2: roze-1 | K2: =IF(C2="","",IFERROR(MATCH(C2,F2:J2,0),"нет")) | L2: =IF(C2="","",IF(K2=1,1,0)) | M2: =IF(C2="","",IF(ISNUMBER(K2),1,0)) | N2: Розовое полусладкое — Фанагория — Розовое полусладкое | O2: Фанагория белое полусладкое — Фанагория — Белое полусладкое | P2: Маринка — Винодельня Покровская — Розовое сухое | Q2: Pink — Золотая Балка — Розовое сухое | R2: Розе — Галицкий и Галицкий — Розовое сухое
A3: 2.69_27-08-2026_14-29-00.webp | B3: нет в каталоге | F3: shato-pino-gravitatsiya-kaberne-sovinon-merlo-krasnoe-suhoe-135 | G3: shato-pino-marselan-merlo-krasnoe-suhoe-13 | H3: shato-pino-sovinon-blan-semilon-beloe-suhoe-115 | I3: shato-pino-shato-pino-koldun-merlo-krasnoe-suhoe-137 | J3: shato-pino-pino-nuar-pino-gri-rozovoe-suhoe-115 | K3: =IF(C3="","",IFERROR(MATCH(C3,F3:J3,0),"нет")) | L3: =IF(C3="","",IF(K3=1,1,0)) | M3: =IF(C3="","",IF(ISNUMBER(K3),1,0)) | N3: Гравитация. Каберне Совиньон - Мерло — Шато Пино — Красное сухое | O3: Марселан - Мерло — Шато Пино — Красное сухое | P3: Совиньон Блан - Семильон — Шато Пино — Белое сухое | Q3: Шато Пино «Колдун» — Шато Пино — Красное сухое | R3: Пино Нуар - Пино Гри — Шато Пино — Розовое сухое
A4: 41.8_22-08-2026_20-56-40.webp | B4: нет в каталоге | F4: bakla-vines-pino-nuar-krasnoe-suhoe-125 | G4: usadba-perovskih-pino-nuar-rezerv-krasnoe-suhoe-122 | H4: usadba-mezyb-shishka-pino-nuar-rozovoe-suhoe-115 | I4: pino-nuar | J4: vaynkraft-pino-nuar-krasnoe-suhoe-13 | K4: =IF(C4="","",IFERROR(MATCH(C4,F4:J4,0),"нет")) | L4: =IF(C4="","",IF(K4=1,1,0)) | M4: =IF(C4="","",IF(ISNUMBER(K4),1,0)) | N4: Пино Нуар — Bakla Vines — Красное сухое | O4: Пино Нуар Резерв — Усадьба Перовских — Красное сухое | P4: Шишка. Пино Нуар — Усадьба Мезыбь — Розовое сухое | Q4: Пино Нуар — Галицкий и Галицкий — Красное сухое | R4: Пино Нуар — ВайнКрафт — Красное сухое
A5: 48.98_02-09-2026_18-34-15.webp | B5: уверенно | C5: denisov_rubin_klaret_krasnaya_strelka | D5: Рубин кларет . Красная стрелка — Denisov Winery — Розовое сухое | F5: denisov_rubin_klaret_krasnaya_strelka | G5: denisov_pino_noir_klaret | H5: gunko-winery-krasnye-gliny-kaberne-fran-krasnoe-suhoe-14 | I5: vinodelnya-78-aligote-otbornoe-beloe-suhoe-12 | J5: vinodelnya-pokrovskaya-pokrovskoe-sladkoe-krasnoe-kaberne-sovinon-13 | K5: =IF(C5="","",IFERROR(MATCH(C5,F5:J5,0),"нет")) | L5: =IF(C5="","",IF(K5=1,1,0)) | M5: =IF(C5="","",IF(ISNUMBER(K5),1,0)) | N5: Рубин кларет . Красная стрелка — Denisov Winery — Розовое сухое | O5: Пино Нуар кларет. Красная стрелка — Denisov Winery — Розовое сухое | P5: Красные Глины — Gunko Winery — Красное сухое | Q5: Алиготе Отборное — Винодельня 78 — Белое сухое | R5: Покровское сладкое красное — Винодельня Покровская — Красное сладкое
A6: 68.81_05-09-2026_15-46-31.webp | B6: нет в каталоге | F6: soyuz-vino-soyuz-vino-muskat-beloe-polusladkoe-11 | G6: vinodelnya-myshako-muskat-avtorskaya-tehnologiya-mono-beloe-suhoe-128 | H6: valeriy-zaharin-muskat-valeriy-zaharin-muskat-ottonel-beloe-polusladkoe-12 | I6: fanagoriya-ledyanoe-vino-muskat-muskat-ottonel-beloe-sladkoe-11 | J6: usadba-markoth-kaberne-sovinon-rezerv-krasnoe-suhoe-13 | K6: =IF(C6="","",IFERROR(MATCH(C6,F6:J6,0),"нет")) | L6: =IF(C6="","",IF(K6=1,1,0)) | M6: =IF(C6="","",IF(ISNUMBER(K6),1,0)) | N6: Союз-Вино Мускат — Союз-Вино — Белое полусладкое | O6: Мускат. Авторская технология. Моно — Мысхако — Белое сухое | P6: Мускат. Валерий Захарьин — Валерий Захарьин — Белое полусладкое | Q6: Ледяное вино. Мускат — Фанагория — Белое сладкое | R6: Каберне Совиньон Резерв — Усадьба Маркотх — Красное сухое
A7: 70.45_04-09-2026_13-35-37.webp | B7: не уверен | C7: fanagoriya-formula-q-kaberne-sovinon-krasnoe-suhoe-135 | D7: Формула Q — Фанагория — Красное сухое | E7: на фото слишком яркая этикетка, в каталоге более темная | F7: fanagoriya-formula-q-kaberne-sovinon-krasnoe-suhoe-135 | G7: fanagoriya-formula-q-saperavi-krasnoe-suhoe-135 | H7: fanagoriya-q-blanc-sovinon-blan-beloe-suhoe-14 | I7: fanagoriya-q-bordeaux-blend-kaberne-sovinon-krasnoe-suhoe-135 | J7: fanagoriya-beloe-polusladkoe | K7: =IF(C7="","",IFERROR(MATCH(C7,F7:J7,0),"нет")) | L7: =IF(C7="","",IF(K7=1,1,0)) | M7: =IF(C7="","",IF(ISNUMBER(K7),1,0)) | N7: Формула Q — Фанагория — Красное сухое | O7: Formula Q — Фанагория — Красное сухое | P7: Q Blanc — Фанагория — Белое сухое | Q7: Q Bordeaux Blend — Фанагория — Красное сухое | R7: Фанагория белое полусладкое — Фанагория — Белое полусладкое
A8: 72.97_09-09-2026_19-38-57.webp | B8: нет в каталоге | F8: shato-pino-gravitatsiya-kaberne-sovinon-merlo-krasnoe-suhoe-135 | G8: shato-pino-marselan-merlo-krasnoe-suhoe-13 | H8: shato-pino-sovinon-blan-semilon-beloe-suhoe-115 | I8: shato-pino-grand-reserve-chardonnay-shardone-beloe-suhoe-125 | J8: shato-pino-blan-de-blan-shardone-beloe-ekstra-bryut-12 | K8: =IF(C8="","",IFERROR(MATCH(C8,F8:J8,0),"нет")) | L8: =IF(C8="","",IF(K8=1,1,0)) | M8: =IF(C8="","",IF(ISNUMBER(K8),1,0)) | N8: Гравитация. Каберне Совиньон - Мерло — Шато Пино — Красное сухое | O8: Марселан - Мерло — Шато Пино — Красное сухое | P8: Совиньон Блан - Семильон — Шато Пино — Белое сухое | Q8: Grand Reserve Chardonnay — Шато Пино — Белое сухое | R8: Блан Де Блан — Шато Пино — Белое экстра брют
A9: 82.33_27-08-2026_10-03-52.webp | B9: уверенно | C9: skalistyj-bereg-shepot-czvetov | D9: Скалистый берег Шепот цветов — Скалистый берег — Белое сухое | F9: skalistyj-bereg-shepot-czvetov | G9: skalistyy-bereg-melodiya-leta-krasnostop-zolotovskiy-rozovoe-suhoe-126 | H9: vysokij-bereg-czvajgelt | I9: skalistyy-bereg-dyhanie-voln-shardone-beloe-suhoe-121 | J9: belbek-rkatsiteli-beloe-suhoe-13 | K9: =IF(C9="","",IFERROR(MATCH(C9,F9:J9,0),"нет")) | L9: =IF(C9="","",IF(K9=1,1,0)) | M9: =IF(C9="","",IF(ISNUMBER(K9),1,0)) | N9: Скалистый берег Шепот цветов — Скалистый берег — Белое сухое | O9: Мелодия лета — Скалистый берег — Розовое сухое | P9: Высокий Берег Цвайгельт — Кубань-Вино — Розовое сухое | Q9: Дыхание волн — Скалистый берег — Белое сухое | R9: Ркацители — Бельбек — Белое сухое
A10: 84.73_07-09-2026_11-07-51.webp | B10: уверенно | C10: zhemchuzhnaya-9-aligote-czitron | D10: Жемчужная 9 Алиготе, Цитрон — АРАТТИ — Белое сухое | F10: zhemchuzhnaya-9-aligote-czitron | G10: zhemchuzhnaya-9-czitron-shardone | H10: zhemchuzhnaya-9-sovinon-blan-aligote | I10: zhemchuzhnaya-9-czitron-shardone-1 | J10: czitronnyj-magaracha-sovinon-blan | K10: =IF(C10="","",IFERROR(MATCH(C10,F10:J10,0),"нет")) | L10: =IF(C10="","",IF(K10=1,1,0)) | M10: =IF(C10="","",IF(ISNUMBER(K10),1,0)) | N10: Жемчужная 9 Алиготе, Цитрон — АРАТТИ — Белое сухое | O10: Жемчужная 9 Цитрон, Шардоне — АРАТТИ — Белое сухое | P10: Жемчужная 9 Совиньон блан, Алиготе — АРАТТИ — Белое сухое | Q10: Жемчужная 9 Цитрон, Шардоне — АРАТТИ — Белое полусладкое | R10: Жемчужная 9 Цитрон, Совиньон блан — АРАТТИ — Белое полусухое
A11: 87.09_22-08-2026_20-57-16.webp | B11: уверенно | C11: pobeda | D11: Победа — Табия — Красное сухое | F11: pobeda | G11: vinodelnya-begildeeva-kaberne-sovinon-krasnoe-suhoe-14 | H11: rubin-golodrigi | I11: kaberne-sovinon-2 | J11: chateau-de-talu-kaberne-sovinon-rezerv-krasnoe-suhoe-14 | K11: =IF(C11="","",IFERROR(MATCH(C11,F11:J11,0),"нет")) | L11: =IF(C11="","",IF(K11=1,1,0)) | M11: =IF(C11="","",IF(ISNUMBER(K11),1,0)) | N11: Победа — Табия — Красное сухое | O11: Каберне Совиньон — Винодельня Бегильдеева — Красное сухое | P11: Рубин Голодриги — Табия — Красное сухое | Q11: Каберне Совиньон — Табия — Красное сухое | R11: Каберне Совиньон Резерв — Chateau de Talu — Красное сухое
A12: 87.54_03-09-2026_13-27-53.webp | B12: уверенно | C12: relikta-relikta-sira-kaberne-fran-krasnoe-suhoe-13 | D12: Реликта Сира, Каберне Фран — Реликта — Красное сухое | F12: relikta-relikta-sira-kaberne-fran-krasnoe-suhoe-13 | G12: relikta-relikta-kaberne-sovinon-krasnoe-suhoe-135 | H12: relikta-relikta-merlo-kaberne-sovinon-krasnoe-suhoe-135 | I12: relikta-relikta-sira-krasnoe-suhoe-13 | J12: relikta-relikta-merlo-krasnoe-suhoe-135 | K12: =IF(C12="","",IFERROR(MATCH(C12,F12:J12,0),"нет")) | L12: =IF(C12="","",IF(K12=1,1,0)) | M12: =IF(C12="","",IF(ISNUMBER(K12),1,0)) | N12: Реликта Сира, Каберне Фран — Реликта — Красное сухое | O12: Реликта Каберне Совиньон — Реликта — Красное сухое | P12: Реликта Мерло, Каберне Совиньон — Реликта — Красное сухое | Q12: Реликта Сира — Реликта — Красное сухое | R12: Реликта Мерло — Реликта — Красное сухое
A13: 87.6_20-08-2026_19-56-56.webp | B13: не уверен | C13: leto-shardone-2023-suhoe-beloe | D13: LETO Шардоне 2023 сухое белое — LETO — Белое сухое | E13: есть такое, но на фото черная этикетка вместо белой | F13: vinodelnya-uzunov-shardone-rezerv-beloe-suhoe-135 | G13: vinodelnya-konstantina-dzitoeva-kd-shardone-beloe-suhoe-128 | H13: vinodelnya-uzunov-nrav-rezerv-krasnostop-zolotovskiy-krasnoe-suhoe-139 | I13: vinodelnya-uzunov-rash-rezerv-risling-reynskiy-beloe-suhoe-127 | J13: vinodelnya-vedernikov-tsimlyanskiy-chernyy-rezerv-krasnoe-suhoe-145 | K13: =IF(C13="","",IFERROR(MATCH(C13,F13:J13,0),"нет")) | L13: =IF(C13="","",IF(K13=1,1,0)) | M13: =IF(C13="","",IF(ISNUMBER(K13),1,0)) | N13: Шардоне Резерв — Винодельня Узунов — Белое сухое | O13: KD Шардоне — Винодельня Константина Дзитоева — Белое сухое | P13: Нрав Резерв — Винодельня Узунов — Красное сухое | Q13: РАШ Резерв — Винодельня Узунов — Белое сухое | R13: Цимлянский Черный Резерв — Ведерниковъ — Красное сухое
A14: 87.81_09-09-2026_17-16-36.webp | B14: не уверен | C14: aya-organic-wine-vineyards-purity-in-chenin-blanc-shenen-blan-beloe-suhoe-11 | D14: Purity in Chenin Blanc — AYA Organic Wine & Vineyards — Белое сухое | E14: есть похожее, но в названии вместо in balance написано in-chenin-blanc | F14: aya-organic-wine-vineyards-purity-in-syrah-sira-rozovoe-suhoe-132 | G14: aya-organic-wine-vineyards-purity-in-trinity-pino-nuar-rozovoe-suhoe-13 | H14: aya-organic-wine-vineyards-purity-in-syrah-sira-krasnoe-suhoe-146 | I14: aya-organic-wine-vineyards-purity-in-merlot-merlo-rozovoe-suhoe-134 | J14: aya-organic-wine-vineyards-purity-in-chenin-blanc-shenen-blan-beloe-suhoe-11 | K14: =IF(C14="","",IFERROR(MATCH(C14,F14:J14,0),"нет")) | L14: =IF(C14="","",IF(K14=1,1,0)) | M14: =IF(C14="","",IF(ISNUMBER(K14),1,0)) | N14: Purity in Syrah — AYA Organic Wine & Vineyards — Розовое сухое | O14: Purity in Trinity — AYA Organic Wine & Vineyards — Розовое сухое | P14: Purity in Syrah — AYA Organic Wine & Vineyards — Красное сухое | Q14: Purity in Merlot — AYA Organic Wine & Vineyards — Розовое сухое | R14: Purity in Chenin Blanc — AYA Organic Wine & Vineyards — Белое сухое
A15: 87.88_28-08-2026_16-56-20.webp | B15: не уверен | C15: massandra-muskatel-belyy-belye-sorta-vinograda-beloe-sladkoe-16 | D15: Мускатель белый — Массандра — Белое сладкое | E15: есть такое, но год урожая отличается | F15: massandra-muskatel-belyy-belye-sorta-vinograda-beloe-sladkoe-16 | G15: massandra-muskatel-rozovyy-belye-sorta-vinograda-rozovoe-sladkoe-16 | H15: massandra-muskatel-chernyy-krasnye-sorta-vinograda-krasnoe-sladkoe-16 | I15: massandra-muskat-belyy-yuzhnoberezhnyy-beloe-sladkoe-16 | J15: massandra-muskat | K15: =IF(C15="","",IFERROR(MATCH(C15,F15:J15,0),"нет")) | L15: =IF(C15="","",IF(K15=1,1,0)) | M15: =IF(C15="","",IF(ISNUMBER(K15),1,0)) | N15: Мускатель белый — Массандра — Белое сладкое | O15: Мускатель розовый — Массандра — Розовое сладкое | P15: Мускатель черный — Массандра — Красное сладкое | Q15: Мускат Белый Южнобережный — Массандра — Белое сладкое | R15: Массандра Мускат — Массандра — Белое сухое
A16: 88.2_05-09-2026_16-29-06.webp | B16: нет в каталоге | F16: inkerman-shato-ruzh | G16: inkermanskiy-zmv-winemakers-selection-saperavi-krasnoe-polusladkoe-12 | H16: vinodelnya-begildeeva-kaberne-sovinon-krasnoe-suhoe-14 | I16: inkerman-shato-blan | J16: kuban-vino-kaberne-de-tamane-kaberne-sovinon-krasnoe-suhoe-125 | K16: =IF(C16="","",IFERROR(MATCH(C16,F16:J16,0),"нет")) | L16: =IF(C16="","",IF(K16=1,1,0)) | M16: =IF(C16="","",IF(ISNUMBER(K16),1,0)) | N16: Inkerman Шато Руж — Инкерманский ЗМВ — Красное полусухое | O16: Winemaker's Selection Саперави — Инкерманский ЗМВ — Красное полусладкое | P16: Каберне Совиньон — Винодельня Бегильдеева — Красное сухое | Q16: Инкерман Шато Блан — Инкерманский ЗМВ — Белое полусухое | R16: Каберне де Тамань — Кубань-Вино — Красное сухое
A17: 88.38_20-08-2026_18-32-58.webp | B17: уверенно | C17: czitronnyj-magaracha-sovinon-blan | D17: Жемчужная 9 Цитрон, Совиньон блан — АРАТТИ — Белое полусухое | F17: czitronnyj-magaracha-sovinon-blan | G17: zhemchuzhnaya-9-aligote-czitron | H17: zhemchuzhnaya-9-czitron-shardone | I17: zhemchuzhnaya-9-czitron-shardone-1 | J17: zhemchuzhnaya-9-sovinon-blan-aligote | K17: =IF(C17="","",IFERROR(MATCH(C17,F17:J17,0),"нет")) | L17: =IF(C17="","",IF(K17=1,1,0)) | M17: =IF(C17="","",IF(ISNUMBER(K17),1,0)) | N17: Жемчужная 9 Цитрон, Совиньон блан — АРАТТИ — Белое полусухое | O17: Жемчужная 9 Алиготе, Цитрон — АРАТТИ — Белое сухое | P17: Жемчужная 9 Цитрон, Шардоне — АРАТТИ — Белое сухое | Q17: Жемчужная 9 Цитрон, Шардоне — АРАТТИ — Белое полусладкое | R17: Жемчужная 9 Совиньон блан, Алиготе — АРАТТИ — Белое сухое
A18: 89.65_19-08-2026_19-48-39.webp | B18: уверенно | C18: rozovoe-zoloto | D18: Розовое золото — Табия — Розовое полусухое | F18: rozovoe-zoloto | G18: bukovinka | H18: roze-2 | I18: rubin-golodrigi | J18: oleg | K18: =IF(C18="","",IFERROR(MATCH(C18,F18:J18,0),"нет")) | L18: =IF(C18="","",IF(K18=1,1,0)) | M18: =IF(C18="","",IF(ISNUMBER(K18),1,0)) | N18: Розовое золото — Табия — Розовое полусухое | O18: Буковинка — Табия — Белое полусухое | P18: Розе — Табия — Розовое сухое | Q18: Рубин Голодриги — Табия — Красное сухое | R18: Олег — Табия — Белое сухое
A19: 90.5_02-09-2026_10-32-11.webp | B19: нет в каталоге | F19: inkerman-shato-ruzh | G19: inkerman-shato-blan | H19: inkerman-muskatnoe-beloe | I19: inkermanskiy-zmv-inkerman-bryut-shardone-beloe-135 | J19: inkermanskiy-zmv-inkerman-rozovoe-polusladkoe-rkatsiteli-12 | K19: =IF(C19="","",IFERROR(MATCH(C19,F19:J19,0),"нет")) | L19: =IF(C19="","",IF(K19=1,1,0)) | M19: =IF(C19="","",IF(ISNUMBER(K19),1,0)) | N19: Inkerman Шато Руж — Инкерманский ЗМВ — Красное полусухое | O19: Инкерман Шато Блан — Инкерманский ЗМВ — Белое полусухое | P19: Inkerman Мускатное белое — Инкерманский ЗМВ — Белое полусладкое | Q19: Inkerman брют — Инкерманский ЗМВ — Белое брют | R19: Инкерман Розовое полусладкое — Инкерманский ЗМВ — Розовое полусладкое
A20: 91.07_20-08-2026_18-37-46.webp | B20: уверенно | C20: aratti-kaberne-sovinon-2021-krasnoe-suhoe | D20: АРАТТИ Каберне Совиньон 2021 красное сухое — АРАТТИ — Красное сухое | F20: aratti-kaberne-sovinon-2021-krasnoe-suhoe | G20: aratti-kaberne-sovinon-2020-krasnoe-suhoe | H20: aratti-kaberne-po-belomu | I20: aratti-sovinon-blan-beloe-polusuhoe | J20: aratti-kaberne-po-belomu-1 | K20: =IF(C20="","",IFERROR(MATCH(C20,F20:J20,0),"нет")) | L20: =IF(C20="","",IF(K20=1,1,0)) | M20: =IF(C20="","",IF(ISNUMBER(K20),1,0)) | N20: АРАТТИ Каберне Совиньон 2021 красное сухое — АРАТТИ — Красное сухое | O20: АРАТТИ Каберне Совиньон 2020 красное сухое — АРАТТИ — Красное сухое | P20: АРАТТИ Каберне по-белому — АРАТТИ — Красное сухое | Q20: АРАТТИ Совиньон блан белое полусухое — АРАТТИ — Белое полусухое | R20: АРАТТИ Каберне по-белому — АРАТТИ — Розовое полусухое
A21: 91.43_02-09-2026_12-08-50.webp | B21: уверенно | C21: merlo-2 | D21: Мерло — Литавщук. Litavshchuk vineyards & winery — Красное сухое | F21: vinodelnya-begildeeva-merlo-krasnoe-suhoe-14 | G21: merlo-2 | H21: vinodelnya-begildeeva-kaberne-sovinon-merlo-krasnoe-suhoe-14 | I21: merlo | J21: vinodelnya-batrak-merlo-rozovoe-suhoe-13 | K21: =IF(C21="","",IFERROR(MATCH(C21,F21:J21,0),"нет")) | L21: =IF(C21="","",IF(K21=1,1,0)) | M21: =IF(C21="","",IF(ISNUMBER(K21),1,0)) | N21: Мерло — Винодельня Бегильдеева — Красное сухое | O21: Мерло — Литавщук. Litavshchuk vineyards & winery — Красное сухое | P21: Каберне Совиньон – Мерло — Винодельня Бегильдеева — Красное сухое | Q21: Мерло — Галицкий и Галицкий — Красное сухое | R21: Мерло — Винодельня Батрак — Розовое сухое
A22: 92.21_19-08-2026_18-57-31.webp | B22: уверенно | C22: belaya-lvicza | D22: Белая Львица белое полусладкое — АРАТТИ — Белое полусладкое | F22: belaya-lvicza | G22: chernaya-lvicza-polusladkoe-krasnoe | H22: aratti-muskat-belyj-suhoe | I22: rozovaya-pantera | J22: aratti-muskat-belyj-polusuhoe | K22: =IF(C22="","",IFERROR(MATCH(C22,F22:J22,0),"нет")) | L22: =IF(C22="","",IF(K22=1,1,0)) | M22: =IF(C22="","",IF(ISNUMBER(K22),1,0)) | N22: Белая Львица белое полусладкое — АРАТТИ — Белое полусладкое | O22: Черная Львица полусладкое красное — АРАТТИ — Красное полусладкое | P22: АРАТТИ Мускат белый сухое — АРАТТИ — Белое сухое | Q22: Розовая Пантера полусладкое розовое — АРАТТИ — Розовое полусладкое | R22: АРАТТИ Мускат белый полусухое — АРАТТИ — Белое полусухое
A23: 92.6_07-09-2026_11-04-40.webp | B23: уверенно | C23: aratti-kaberne-sovinon-2020-krasnoe-suhoe | D23: АРАТТИ Каберне Совиньон 2020 красное сухое — АРАТТИ — Красное сухое | F23: aratti-kaberne-sovinon-2020-krasnoe-suhoe | G23: aratti-kaberne-sovinon-2021-krasnoe-suhoe | H23: artvin-kaberne-sovinon-grand-rezerv-krasnoe-suhoe-13 | I23: vinodelnya-begildeeva-kaberne-sovinon-krasnoe-suhoe-14 | J23: aratti-sovinon-blan-beloe-polusuhoe | K23: =IF(C23="","",IFERROR(MATCH(C23,F23:J23,0),"нет")) | L23: =IF(C23="","",IF(K23=1,1,0)) | M23: =IF(C23="","",IF(ISNUMBER(K23),1,0)) | N23: АРАТТИ Каберне Совиньон 2020 красное сухое — АРАТТИ — Красное сухое | O23: АРАТТИ Каберне Совиньон 2021 красное сухое — АРАТТИ — Красное сухое | P23: Каберне Совиньон Гранд Резерв — Артвин — Красное сухое | Q23: Каберне Совиньон — Винодельня Бегильдеева — Красное сухое | R23: АРАТТИ Совиньон блан белое полусухое — АРАТТИ — Белое полусухое
A24: 92.94_21-08-2026_19-37-08.webp | B24: не уверен | C24: denisov-winery-sovinon-blan-beloe-suhoe-115 | D24: Совиньон Блан — Denisov Winery — Белое сухое | E24: есть такое, но этикетка черная, а не белая | F24: denisov-winery-sovinon-blan-beloe-suhoe-115 | G24: dubinin-winery-sovinon-blan-beloe-suhoe-12 | H24: sovinon-blan | I24: zhemchuzhnaya-9-sovinon-blan-aligote | J24: blagolyubov-sovinon-blan-beloe-suhoe-125 | K24: =IF(C24="","",IFERROR(MATCH(C24,F24:J24,0),"нет")) | L24: =IF(C24="","",IF(K24=1,1,0)) | M24: =IF(C24="","",IF(ISNUMBER(K24),1,0)) | N24: Совиньон Блан — Denisov Winery — Белое сухое | O24: Совиньон Блан — Dubinin Winery — Белое сухое | P24: Совиньон Блан — Литавщук. Litavshchuk vineyards & winery — Белое полусладкое | Q24: Жемчужная 9 Совиньон блан, Алиготе — АРАТТИ — Белое сухое | R24: Совиньон Блан — Благолюбов — Белое сухое
A25: 92.96_19-08-2026_21-07-12.webp | B25: уверенно | C25: aratti-kaberne-sovinon-2020-krasnoe-suhoe | D25: АРАТТИ Каберне Совиньон 2020 красное сухое — АРАТТИ — Красное сухое | F25: aratti-kaberne-sovinon-2020-krasnoe-suhoe | G25: aratti-kaberne-sovinon-2021-krasnoe-suhoe | H25: artvin-kaberne-sovinon-grand-rezerv-krasnoe-suhoe-13 | I25: vinodelnya-begildeeva-kaberne-sovinon-krasnoe-suhoe-14 | J25: aratti-vremena-goda-saperavi-leto | K25: =IF(C25="","",IFERROR(MATCH(C25,F25:J25,0),"нет")) | L25: =IF(C25="","",IF(K25=1,1,0)) | M25: =IF(C25="","",IF(ISNUMBER(K25),1,0)) | N25: АРАТТИ Каберне Совиньон 2020 красное сухое — АРАТТИ — Красное сухое | O25: АРАТТИ Каберне Совиньон 2021 красное сухое — АРАТТИ — Красное сухое | P25: Каберне Совиньон Гранд Резерв — Артвин — Красное сухое | Q25: Каберне Совиньон — Винодельня Бегильдеева — Красное сухое | R25: АРАТТИ Времена Года Саперави Лето — АРАТТИ — Красное сухое
A26: 92.99_02-09-2026_04-20-19.webp | B26: нет в каталоге | F26: vinodelnya-myshako-rose-de-noirs-pino-nuar-rozovoe-bryut-123 | G26: rozovaya-pantera | H26: usadba-divnomorskoe-rose-vione-rozovoe-suhoe-125 | I26: kuban-vino-vysokiy-bereg-grafit-roze-kaberne-sovinon-rozovoe-suhoe-12 | J26: mont-blanc-blanc-de-blancs | K26: =IF(C26="","",IFERROR(MATCH(C26,F26:J26,0),"нет")) | L26: =IF(C26="","",IF(K26=1,1,0)) | M26: =IF(C26="","",IF(ISNUMBER(K26),1,0)) | N26: Rose De Noirs — Мысхако — Розовое брют | O26: Розовая Пантера полусладкое розовое — АРАТТИ — Розовое полусладкое | P26: Rose — Усадьба Дивноморское — Розовое сухое | Q26: Высокий Берег Графит Розе — Кубань-Вино — Розовое сухое | R26: Mont Blanc, Blanc de Blancs — Шато АЛВИСА — Белое брют
A27: 93.31_05-09-2026_13-39-37.webp | B27: уверенно | C27: golubitskoe-estate-noble-selection-red-blend-kaberne-sovinon-krasnoe-suhoe-136 | D27: Noble Selection Red Blend — Golubitskoe Estate — Красное сухое | F27: golubitskoe-estate-noble-selection-red-blend-kaberne-sovinon-krasnoe-suhoe-136 | G27: golubitskoe-estate-kaberne-sovinon-noble-selection-krasnoe-suhoe-133 | H27: golubitskoe-estate-kaberne-sovinon-rezerv-krasnoe-suhoe-125 | I27: golubitskoe-estate-noble-selection-white-blend-shardone-beloe-suhoe-135 | J27: pomeste-golubitskoe-kaberne-sovinon-rezerv-krasnoe-suhoe-143 | K27: =IF(C27="","",IFERROR(MATCH(C27,F27:J27,0),"нет")) | L27: =IF(C27="","",IF(K27=1,1,0)) | M27: =IF(C27="","",IF(ISNUMBER(K27),1,0)) | N27: Noble Selection Red Blend — Golubitskoe Estate — Красное сухое | O27: Каберне Совиньон Noble Selection — Golubitskoe Estate — Красное сухое | P27: Каберне Совиньон Резерв — Golubitskoe Estate — Красное сухое | Q27: Noble Selection White Blend — Golubitskoe Estate — Белое сухое | R27: Каберне Совиньон Резерв — Golubitskoe Estate — Красное сухое
A28: 93.43_05-09-2026_13-34-45.webp | B28: уверенно | C28: denisov_pet_nat_rubin | D28: Пет-Нат Рубин — Denisov Winery — Розовое экстра брют | F28: denisov-winery-petnat-risling-beloe-ekstra-bryut-10 | G28: denisov-winery-petnat-rkatsiteli-beloe-ekstra-bryut-107 | H28: denisov-winery-petnat-tsitron-risling-tsitronnyy-magaracha-beloe-ekstra-bryut-102 | I28: denisov_pet_nat_rubin | J28: fioletovyj-rannij-petnat | K28: =IF(C28="","",IFERROR(MATCH(C28,F28:J28,0),"нет")) | L28: =IF(C28="","",IF(K28=1,1,0)) | M28: =IF(C28="","",IF(ISNUMBER(K28),1,0)) | N28: Петнат Рислинг — Denisov Winery — Белое экстра брют | O28: Петнат Ркацители — Denisov Winery — Белое экстра брют | P28: Петнат Цитрон - Рислинг — Denisov Winery — Белое экстра брют | Q28: Пет-Нат Рубин — Denisov Winery — Розовое экстра брют | R28: Фиолетовый Ранний петнат — Гусевъ — Белое экстра брют
A29: 93.68_19-08-2026_20-44-28.webp | B29: уверенно | C29: zakat-denisov-vajneri | D29: Закат. Денисов Вайнери — Denisov Winery — Розовое сухое | F29: zakat-denisov-vajneri | G29: zhemchuzhnaya-9-pino-nuar-muskat-rozovyj | H29: rozovaya-pantera | I29: vinodelnya-78-muskat-polusladkoe-muskat-ottonel-beloe-115 | J29: zhemchuzhnaya-9-pino-nuar-muskat-rozovyj-1 | K29: =IF(C29="","",IFERROR(MATCH(C29,F29:J29,0),"нет")) | L29: =IF(C29="","",IF(K29=1,1,0)) | M29: =IF(C29="","",IF(ISNUMBER(K29),1,0)) | N29: Закат. Денисов Вайнери — Denisov Winery — Розовое сухое | O29: Жемчужная 9 Пино Нуар, Мускат Розовый — АРАТТИ — Розовое сухое | P29: Розовая Пантера полусладкое розовое — АРАТТИ — Розовое полусладкое | Q29: Мускат полусладкое — Винодельня 78 — Белое полусладкое | R29: Жемчужная 9 Пино Нуар, Мускат розовый — АРАТТИ — Розовое полусухое
A30: 93.84_02-09-2026_17-13-04.webp | B30: уверенно | C30: zakat-denisov-vajneri | D30: Закат. Денисов Вайнери — Denisov Winery — Розовое сухое | F30: zakat-denisov-vajneri | G30: vinodelnya-78-muskat-polusladkoe-muskat-ottonel-beloe-115 | H30: rozovaya-pantera | I30: zhemchuzhnaya-9-pino-nuar-muskat-rozovyj | J30: vinodelnya-vedernikov-tsimlyanskiy-chernyy-rozovyy-rozovoe-suhoe-125 | K30: =IF(C30="","",IFERROR(MATCH(C30,F30:J30,0),"нет")) | L30: =IF(C30="","",IF(K30=1,1,0)) | M30: =IF(C30="","",IF(ISNUMBER(K30),1,0)) | N30: Закат. Денисов Вайнери — Denisov Winery — Розовое сухое | O30: Мускат полусладкое — Винодельня 78 — Белое полусладкое | P30: Розовая Пантера полусладкое розовое — АРАТТИ — Розовое полусладкое | Q30: Жемчужная 9 Пино Нуар, Мускат Розовый — АРАТТИ — Розовое сухое | R30: Цимлянский Черный розовый — Ведерниковъ — Розовое сухое
A31: 93.95_05-09-2026_15-29-36.webp | B31: нет в каталоге | F31: novyy-svet-dom-shampanskih-vin-igristoe-vino-vyderzhannoe-polusladkoe-rozovoe-novyy-svet-pino-fran-135 | G31: abrau-dyurso-imperial-kyuve-pino-nuar-rozovoe-bryut-125 | H31: valeriy-zaharin-aligote-avtorskoe-valeriy-zaharin-beloe-bryut-115 | I31: valeriy-zaharin-aligote-burlyuk-beloe-bryut-115 | J31: rozovoe-bryut-1 | K31: =IF(C31="","",IFERROR(MATCH(C31,F31:J31,0),"нет")) | L31: =IF(C31="","",IF(K31=1,1,0)) | M31: =IF(C31="","",IF(ISNUMBER(K31),1,0)) | N31: Игристое вино выдержанное полусладкое розовое «Новый Свет. Пино Фран» — Новый Свет. Дом шампанских вин — Розовое полусладкое | O31: Империал Кюве — Абрау-Дюрсо — Розовое брют | P31: Алиготе. Авторское. Валерий Захарьин — Валерий Захарьин — Белое брют | Q31: Алиготе. Бурлюк — Валерий Захарьин — Белое брют | R31: Розовое брют — Золотая Балка — Розовое брют
A32: 93.97_28-08-2026_16-02-48.webp | B32: нет в каталоге | F32: golubitskoe-estate-chardonnay | G32: golubitskoe-estate-shardone-rezerv-beloe-suhoe-135 | H32: golubitskoe-estate-shardone-noble-selection-barrel-touch-beloe-suhoe-135 | I32: golubitskoe-estate-sovinon-blan-beloe-suhoe-11 | J32: pomeste-golubitskoe-shardone-rezerv-beloe-suhoe-132 | K32: =IF(C32="","",IFERROR(MATCH(C32,F32:J32,0),"нет")) | L32: =IF(C32="","",IF(K32=1,1,0)) | M32: =IF(C32="","",IF(ISNUMBER(K32),1,0)) | N32: Golubitskoe Estate Chardonnay — Поместье Голубицкое — Белое сухое | O32: Шардоне Резерв — Golubitskoe Estate — Белое сухое | P32: Шардоне Noble Selection Barrel Touch — Golubitskoe Estate — Белое сухое | Q32: Совиньон Блан — Golubitskoe Estate — Белое сухое | R32: Шардоне Резерв — Golubitskoe Estate — Белое сухое
A33: 94.02_24-08-2026_17-46-57.webp | B33: уверенно | C33: rubin-golodrigi | D33: Рубин Голодриги — Табия — Красное сухое | F33: rubin-golodrigi | G33: kaberne-sovinon-2 | H33: bukovinka | I33: oleg | J33: roze-2 | K33: =IF(C33="","",IFERROR(MATCH(C33,F33:J33,0),"нет")) | L33: =IF(C33="","",IF(K33=1,1,0)) | M33: =IF(C33="","",IF(ISNUMBER(K33),1,0)) | N33: Рубин Голодриги — Табия — Красное сухое | O33: Каберне Совиньон — Табия — Красное сухое | P33: Буковинка — Табия — Белое полусухое | Q33: Олег — Табия — Белое сухое | R33: Розе — Табия — Розовое сухое
A34: 94.43_05-09-2026_15-29-25.webp | B34: нет в каталоге | F34: novyy-svet-dom-shampanskih-vin-igristoe-vino-vyderzhannoe-polusladkoe-rozovoe-novyy-svet-pino-fran-135 | G34: rozovoe-bryut-1 | H34: vinodelnya-78-muskat-polusladkoe-muskat-ottonel-beloe-115 | I34: balaklava-bryut-rezerv | J34: valeriy-zaharin-aligote-avtorskoe-valeriy-zaharin-beloe-bryut-115 | K34: =IF(C34="","",IFERROR(MATCH(C34,F34:J34,0),"нет")) | L34: =IF(C34="","",IF(K34=1,1,0)) | M34: =IF(C34="","",IF(ISNUMBER(K34),1,0)) | N34: Игристое вино выдержанное полусладкое розовое «Новый Свет. Пино Фран» — Новый Свет. Дом шампанских вин — Розовое полусладкое | O34: Розовое брют — Золотая Балка — Розовое брют | P34: Мускат полусладкое — Винодельня 78 — Белое полусладкое | Q34: Балаклава Брют Резерв — Золотая Балка — Белое брют | R34: Алиготе. Авторское. Валерий Захарьин — Валерий Захарьин — Белое брют
A35: 94.55_02-09-2026_16-53-08.webp | B35: уверенно | C35: denisov_pazori_risling | D35: Пазори Рислинг — Denisov Winery — Белое брют | F35: denisov-winery-pino-nuar-shardone-ekstra-bryut-beloe-125 | G35: denisov_pazori_risling | H35: vinodelnya-zhakov-saperavi-vyderzhannoe-krasnoe-suhoe-115 | I35: vinodelnya-uzunov-nrav-krasnostop-zolotovskiy-krasnoe-suhoe-132 | J35: usadba-aleksandrovskaya-bubnovyy-valet-kaberne-sovinon-krasnoe-polusladkoe-13 | K35: =IF(C35="","",IFERROR(MATCH(C35,F35:J35,0),"нет")) | L35: =IF(C35="","",IF(K35=1,1,0)) | M35: =IF(C35="","",IF(ISNUMBER(K35),1,0)) | N35: Пино Нуар - Шардоне экстра брют — Denisov Winery — Белое экстра брют | O35: Пазори Рислинг — Denisov Winery — Белое брют | P35: Саперави выдержанное — Винодельня Жаков — Красное сухое | Q35: Нрав — Винодельня Узунов — Красное сухое | R35: Бубновый Валет — Усадьба Александровская — Красное полусладкое
A36: 94.72_21-08-2026_15-41-48.webp | B36: не уверен | C36: derbent-vino-desono-kaberne-sovinon-krasnoe-suhoe-125 | D36: Дэсоно Каберне Совиньон — Дербент Вино — Красное сухое | E36: есть такое, но надпись внизу несоответствует, она больше. но фактически одно и то же | F36: derbent-vino-desono-kaberne-sovinon-krasnoe-suhoe-125 | G36: derbent-vino-desono-kaberne-fran-krasnoe-suhoe-125 | H36: derbent-vino-desono-merlo-krasnoe-suhoe-125 | I36: derbent-vino-desono-risling-beloe-suhoe-125 | J36: derbent-vino-desono-shardone-beloe-suhoe-125 | K36: =IF(C36="","",IFERROR(MATCH(C36,F36:J36,0),"нет")) | L36: =IF(C36="","",IF(K36=1,1,0)) | M36: =IF(C36="","",IF(ISNUMBER(K36),1,0)) | N36: Дэсоно Каберне Совиньон — Дербент Вино — Красное сухое | O36: Дэсоно Каберне Фран — Дербент Вино — Красное сухое | P36: Дэсоно Мерло — Дербент Вино — Красное сухое | Q36: Дэсоно Рислинг — Дербент Вино — Белое сухое | R36: Дэсоно Шардоне — Дербент Вино — Белое сухое
A37: 94.7_25-08-2026_15-52-07.webp | B37: уверенно | C37: czitronnyj-magaracha-sovinon-blan | D37: Жемчужная 9 Цитрон, Совиньон блан — АРАТТИ — Белое полусухое | F37: czitronnyj-magaracha-sovinon-blan | G37: zhemchuzhnaya-9-czitron-shardone-1 | H37: zhemchuzhnaya-9-aligote-czitron | I37: zhemchuzhnaya-9-czitron-shardone | J37: zhemchuzhnaya-9-sovinon-blan-aligote | K37: =IF(C37="","",IFERROR(MATCH(C37,F37:J37,0),"нет")) | L37: =IF(C37="","",IF(K37=1,1,0)) | M37: =IF(C37="","",IF(ISNUMBER(K37),1,0)) | N37: Жемчужная 9 Цитрон, Совиньон блан — АРАТТИ — Белое полусухое | O37: Жемчужная 9 Цитрон, Шардоне — АРАТТИ — Белое полусладкое | P37: Жемчужная 9 Алиготе, Цитрон — АРАТТИ — Белое сухое | Q37: Жемчужная 9 Цитрон, Шардоне — АРАТТИ — Белое сухое | R37: Жемчужная 9 Совиньон блан, Алиготе — АРАТТИ — Белое сухое
A38: 94.83_27-08-2026_14-29-28.webp | B38: нет в каталоге | F38: shato-pino-gravitatsiya-kaberne-sovinon-merlo-krasnoe-suhoe-135 | G38: shato-pino-sovinon-blan-semilon-beloe-suhoe-115 | H38: shato-pino-marselan-merlo-krasnoe-suhoe-13 | I38: shato-pino-shardone-beloe-suhoe-125 | J38: shato-pino-aligote-rkatsiteli-beloe-suhoe-12 | K38: =IF(C38="","",IFERROR(MATCH(C38,F38:J38,0),"нет")) | L38: =IF(C38="","",IF(K38=1,1,0)) | M38: =IF(C38="","",IF(ISNUMBER(K38),1,0)) | N38: Гравитация. Каберне Совиньон - Мерло — Шато Пино — Красное сухое | O38: Совиньон Блан - Семильон — Шато Пино — Белое сухое | P38: Марселан - Мерло — Шато Пино — Красное сухое | Q38: Шардоне — Шато Пино — Белое сухое | R38: Алиготе - Ркацители белое сухое — Шато Пино — Белое сухое
A39: 94.8_01-09-2026_10-10-02.webp | B39: нет в каталоге | F39: massandra-portveyn-krasnyy-alushta-krasnye-sorta-vinograda-krasnoe-sladkoe-17 | G39: kaberne-sovinon | H39: vinodelnya-pokrovskaya-pokrovskoe-sladkoe-krasnoe-kaberne-sovinon-13 | I39: massandra-muskat-belyy-yuzhnoberezhnyy-beloe-sladkoe-16 | J39: massandra-portveyn-krasnyy-livadiya-kaberne-sovinon-krasnoe-sladkoe-185 | K39: =IF(C39="","",IFERROR(MATCH(C39,F39:J39,0),"нет")) | L39: =IF(C39="","",IF(K39=1,1,0)) | M39: =IF(C39="","",IF(ISNUMBER(K39),1,0)) | N39: Портвейн красный Алушта — Массандра — Красное сладкое | O39: Каберне Совиньон — Массандра — Красное сладкое | P39: Покровское сладкое красное — Винодельня Покровская — Красное сладкое | Q39: Мускат Белый Южнобережный — Массандра — Белое сладкое | R39: Портвейн красный Ливадия — Массандра — Красное сладкое
A40: 94.94_05-09-2026_15-04-50.webp | B40: не уверен | C40: denisov-winery-sovinon-blan-beloe-suhoe-115 | D40: Совиньон Блан — Denisov Winery — Белое сухое | E40: этикетка немного другая. в slug черная, а на фото белая | F40: denisov-winery-sovinon-blan-beloe-suhoe-115 | G40: dubinin-winery-sovinon-blan-beloe-suhoe-12 | H40: imenie-sikory-sovinon-blan-sikory-beloe-suhoe-13 | I40: zhemchuzhnaya-9-sovinon-blan-aligote | J40: levokumskoe-sovinon-blan-beloe-suhoe-10 | K40: =IF(C40="","",IFERROR(MATCH(C40,F40:J40,0),"нет")) | L40: =IF(C40="","",IF(K40=1,1,0)) | M40: =IF(C40="","",IF(ISNUMBER(K40),1,0)) | N40: Совиньон Блан — Denisov Winery — Белое сухое | O40: Совиньон Блан — Dubinin Winery — Белое сухое | P40: Совиньон Блан Сикоры — Имение Сикоры — Белое сухое | Q40: Жемчужная 9 Совиньон блан, Алиготе — АРАТТИ — Белое сухое | R40: Совиньон Блан — Левокумское — Белое сухое
...

Sheet С OCR
A1: Фото | B1: Статус разметки | C1: target | D1: target: вино | E1: Комментарий разметчика | F1: top-1 | G1: top-2 | H1: top-3 | I1: top-4 | J1: top-5 | K1: Ранг target | L1: Верно top-1 | M1: Верно top-5 | N1: top-1: вино | O1: top-2: вино | P1: top-3: вино | Q1: top-4: вино | R1: top-5: вино
A2: 1.73_06-09-2026_14-54-06.webp | B2: не уверен | C2: fanagoriya-rose-kaberne-fran-rozovoe-suhoe-13 | D2: Rose. Каберне Фран — Фанагория — Розовое сухое | E2: договоримся так, после __ я буду писать свои комментарии. этого вина нет в наборе, но я не уверен | F2: rozovoe-polusladkoe | G2: fanagoriya-beloe-polusladkoe | H2: fanagoriya-fanagoria-extra-brut-rose-2019-pino-nuar-igristoe-bryut-rozovoe-ekstra-bryut-12 | I2: fanagoriya-zelyonoe-vino-risling-tsitronnyy-magaracha-merlo-rozovoe-polusuhoe-11 | J2: fanagoriya-rose-saperavi-rozovoe-polusuhoe-125 | K2: =IF(C2="","",IFERROR(MATCH(C2,F2:J2,0),"нет")) | L2: =IF(C2="","",IF(K2=1,1,0)) | M2: =IF(C2="","",IF(ISNUMBER(K2),1,0)) | N2: Розовое полусладкое — Фанагория — Розовое полусладкое | O2: Фанагория белое полусладкое — Фанагория — Белое полусладкое | P2: Fanagoria Extra Brut Rose 2019 — Фанагория — Розовое экстра брют | Q2: Зелёное вино. Рислинг - Цитронный Магарача - Мерло — Фанагория — Розовое полусухое | R2: Rose. Саперави — Фанагория — Розовое полусухое
A3: 2.69_27-08-2026_14-29-00.webp | B3: нет в каталоге | F3: shato-pino-gravitatsiya-kaberne-sovinon-merlo-krasnoe-suhoe-135 | G3: shato-pino-marselan-merlo-krasnoe-suhoe-13 | H3: shato-pino-sovinon-blan-semilon-beloe-suhoe-115 | I3: shato-pino-shato-pino-koldun-merlo-krasnoe-suhoe-137 | J3: shato-pino-grand-reserve-pinot-noir-pino-nuar-krasnoe-suhoe-135 | K3: =IF(C3="","",IFERROR(MATCH(C3,F3:J3,0),"нет")) | L3: =IF(C3="","",IF(K3=1,1,0)) | M3: =IF(C3="","",IF(ISNUMBER(K3),1,0)) | N3: Гравитация. Каберне Совиньон - Мерло — Шато Пино — Красное сухое | O3: Марселан - Мерло — Шато Пино — Красное сухое | P3: Совиньон Блан - Семильон — Шато Пино — Белое сухое | Q3: Шато Пино «Колдун» — Шато Пино — Красное сухое | R3: Grand Reserve Pinot Noir — Шато Пино — Красное сухое
A4: 41.8_22-08-2026_20-56-40.webp | B4: нет в каталоге | F4: bakla-vines-pino-nuar-krasnoe-suhoe-125 | G4: usadba-perovskih-pino-nuar-rezerv-krasnoe-suhoe-122 | H4: usadba-mezyb-shishka-pino-nuar-rozovoe-suhoe-115 | I4: pino-nuar-2025 | J4: pino-nuar | K4: =IF(C4="","",IFERROR(MATCH(C4,F4:J4,0),"нет")) | L4: =IF(C4="","",IF(K4=1,1,0)) | M4: =IF(C4="","",IF(ISNUMBER(K4),1,0)) | N4: Пино Нуар — Bakla Vines — Красное сухое | O4: Пино Нуар Резерв — Усадьба Перовских — Красное сухое | P4: Шишка. Пино Нуар — Усадьба Мезыбь — Розовое сухое | Q4: Пино Нуар, 2025 — Винодельня Братьев Мельниковых — Розовое сухое | R4: Пино Нуар — Галицкий и Галицкий — Красное сухое
A5: 48.98_02-09-2026_18-34-15.webp | B5: уверенно | C5: denisov_rubin_klaret_krasnaya_strelka | D5: Рубин кларет . Красная стрелка — Denisov Winery — Розовое сухое | F5: denisov_rubin_klaret_krasnaya_strelka | G5: denisov_pino_noir_klaret | H5: gunko-winery-krasnye-gliny-kaberne-fran-krasnoe-suhoe-14 | I5: vinodelnya-pokrovskaya-pokrovskoe-sladkoe-krasnoe-kaberne-sovinon-13 | J5: vinodelnya-konstantina-dzitoeva-kd-rezerv-merlo-krasnoe-suhoe-12 | K5: =IF(C5="","",IFERROR(MATCH(C5,F5:J5,0),"нет")) | L5: =IF(C5="","",IF(K5=1,1,0)) | M5: =IF(C5="","",IF(ISNUMBER(K5),1,0)) | N5: Рубин кларет . Красная стрелка — Denisov Winery — Розовое сухое | O5: Пино Нуар кларет. Красная стрелка — Denisov Winery — Розовое сухое | P5: Красные Глины — Gunko Winery — Красное сухое | Q5: Покровское сладкое красное — Винодельня Покровская — Красное сладкое | R5: KD Резерв — Винодельня Константина Дзитоева — Красное сухое
A6: 68.81_05-09-2026_15-46-31.webp | B6: нет в каталоге | F6: fanagoriya-velvet-season-muskat-ottonel-beloe-sladkoe-13 | G6: fanagoriya-velvet-season-risling-beloe-sladkoe-12 | H6: soyuz-vino-soyuz-vino-muskat-beloe-polusladkoe-11 | I6: vinodelnya-myshako-muskat-avtorskaya-tehnologiya-mono-beloe-suhoe-128 | J6: valeriy-zaharin-muskat-valeriy-zaharin-muskat-ottonel-beloe-polusladkoe-12 | K6: =IF(C6="","",IFERROR(MATCH(C6,F6:J6,0),"нет")) | L6: =IF(C6="","",IF(K6=1,1,0)) | M6: =IF(C6="","",IF(ISNUMBER(K6),1,0)) | N6: Velvet Season — Фанагория — Белое сладкое | O6: Velvet Season — Фанагория — Белое сладкое | P6: Союз-Вино Мускат — Союз-Вино — Белое полусладкое | Q6: Мускат. Авторская технология. Моно — Мысхако — Белое сухое | R6: Мускат. Валерий Захарьин — Валерий Захарьин — Белое полусладкое
A7: 70.45_04-09-2026_13-35-37.webp | B7: не уверен | C7: fanagoriya-formula-q-kaberne-sovinon-krasnoe-suhoe-135 | D7: Формула Q — Фанагория — Красное сухое | E7: на фото слишком яркая этикетка, в каталоге более темная | F7: fanagoriya-formula-q-saperavi-krasnoe-suhoe-135 | G7: fanagoriya-formula-q-kaberne-sovinon-krasnoe-suhoe-135 | H7: fanagoriya-q-blanc-sovinon-blan-beloe-suhoe-14 | I7: fanagoriya-q-bordeaux-blend-kaberne-sovinon-krasnoe-suhoe-135 | J7: fanagoriya-beloe-polusladkoe | K7: =IF(C7="","",IFERROR(MATCH(C7,F7:J7,0),"нет")) | L7: =IF(C7="","",IF(K7=1,1,0)) | M7: =IF(C7="","",IF(ISNUMBER(K7),1,0)) | N7: Formula Q — Фанагория — Красное сухое | O7: Формула Q — Фанагория — Красное сухое | P7: Q Blanc — Фанагория — Белое сухое | Q7: Q Bordeaux Blend — Фанагория — Красное сухое | R7: Фанагория белое полусладкое — Фанагория — Белое полусладкое
A8: 72.97_09-09-2026_19-38-57.webp | B8: нет в каталоге | F8: shato-pino-gravitatsiya-kaberne-sovinon-merlo-krasnoe-suhoe-135 | G8: shato-pino-marselan-merlo-krasnoe-suhoe-13 | H8: shato-pino-grand-reserve-pinot-noir-pino-nuar-krasnoe-suhoe-135 | I8: shato-pino-sovinon-blan-semilon-beloe-suhoe-115 | J8: shato-pino-grand-reserve-chardonnay-shardone-beloe-suhoe-125 | K8: =IF(C8="","",IFERROR(MATCH(C8,F8:J8,0),"нет")) | L8: =IF(C8="","",IF(K8=1,1,0)) | M8: =IF(C8="","",IF(ISNUMBER(K8),1,0)) | N8: Гравитация. Каберне Совиньон - Мерло — Шато Пино — Красное сухое | O8: Марселан - Мерло — Шато Пино — Красное сухое | P8: Grand Reserve Pinot Noir — Шато Пино — Красное сухое | Q8: Совиньон Блан - Семильон — Шато Пино — Белое сухое | R8: Grand Reserve Chardonnay — Шато Пино — Белое сухое
A9: 82.33_27-08-2026_10-03-52.webp | B9: уверенно | C9: skalistyj-bereg-shepot-czvetov | D9: Скалистый берег Шепот цветов — Скалистый берег — Белое сухое | F9: skalistyj-bereg-shepot-czvetov | G9: skalistyy-bereg-melodiya-leta-krasnostop-zolotovskiy-rozovoe-suhoe-126 | H9: skalistyy-bereg-dyhanie-voln-shardone-beloe-suhoe-121 | I9: vysokij-bereg-czvajgelt | J9: kuban-vino-vysokiy-bereg-grafit-roze-kaberne-sovinon-rozovoe-suhoe-12 | K9: =IF(C9="","",IFERROR(MATCH(C9,F9:J9,0),"нет")) | L9: =IF(C9="","",IF(K9=1,1,0)) | M9: =IF(C9="","",IF(ISNUMBER(K9),1,0)) | N9: Скалистый берег Шепот цветов — Скалистый берег — Белое сухое | O9: Мелодия лета — Скалистый берег — Розовое сухое | P9: Дыхание волн — Скалистый берег — Белое сухое | Q9: Высокий Берег Цвайгельт — Кубань-Вино — Розовое сухое | R9: Высокий Берег Графит Розе — Кубань-Вино — Розовое сухое
A10: 84.73_07-09-2026_11-07-51.webp | B10: уверенно | C10: zhemchuzhnaya-9-aligote-czitron | D10: Жемчужная 9 Алиготе, Цитрон — АРАТТИ — Белое сухое | F10: zhemchuzhnaya-9-aligote-czitron | G10: zhemchuzhnaya-9-czitron-shardone | H10: zhemchuzhnaya-9-czitron-shardone-1 | I10: zhemchuzhnaya-9-sovinon-blan-aligote | J10: czitronnyj-magaracha-sovinon-blan | K10: =IF(C10="","",IFERROR(MATCH(C10,F10:J10,0),"нет")) | L10: =IF(C10="","",IF(K10=1,1,0)) | M10: =IF(C10="","",IF(ISNUMBER(K10),1,0)) | N10: Жемчужная 9 Алиготе, Цитрон — АРАТТИ — Белое сухое | O10: Жемчужная 9 Цитрон, Шардоне — АРАТТИ — Белое сухое | P10: Жемчужная 9 Цитрон, Шардоне — АРАТТИ — Белое полусладкое | Q10: Жемчужная 9 Совиньон блан, Алиготе — АРАТТИ — Белое сухое | R10: Жемчужная 9 Цитрон, Совиньон блан — АРАТТИ — Белое полусухое
A11: 87.09_22-08-2026_20-57-16.webp | B11: уверенно | C11: pobeda | D11: Победа — Табия — Красное сухое | F11: pobeda | G11: rubin-golodrigi | H11: kaberne-sovinon-2 | I11: vinodelnya-begildeeva-kaberne-sovinon-krasnoe-suhoe-14 | J11: bukovinka | K11: =IF(C11="","",IFERROR(MATCH(C11,F11:J11,0),"нет")) | L11: =IF(C11="","",IF(K11=1,1,0)) | M11: =IF(C11="","",IF(ISNUMBER(K11),1,0)) | N11: Победа — Табия — Красное сухое | O11: Рубин Голодриги — Табия — Красное сухое | P11: Каберне Совиньон — Табия — Красное сухое | Q11: Каберне Совиньон — Винодельня Бегильдеева — Красное сухое | R11: Буковинка — Табия — Белое полусухое
A12: 87.54_03-09-2026_13-27-53.webp | B12: уверенно | C12: relikta-relikta-sira-kaberne-fran-krasnoe-suhoe-13 | D12: Реликта Сира, Каберне Фран — Реликта — Красное сухое | F12: relikta-relikta-sira-kaberne-fran-krasnoe-suhoe-13 | G12: relikta-relikta-sira-krasnoe-suhoe-13 | H12: relikta-relikta-kaberne-sovinon-krasnoe-suhoe-135 | I12: relikta-relikta-merlo-kaberne-sovinon-krasnoe-suhoe-135 | J12: relikta-relikta-merlo-krasnoe-suhoe-135 | K12: =IF(C12="","",IFERROR(MATCH(C12,F12:J12,0),"нет")) | L12: =IF(C12="","",IF(K12=1,1,0)) | M12: =IF(C12="","",IF(ISNUMBER(K12),1,0)) | N12: Реликта Сира, Каберне Фран — Реликта — Красное сухое | O12: Реликта Сира — Реликта — Красное сухое | P12: Реликта Каберне Совиньон — Реликта — Красное сухое | Q12: Реликта Мерло, Каберне Совиньон — Реликта — Красное сухое | R12: Реликта Мерло — Реликта — Красное сухое
A13: 87.6_20-08-2026_19-56-56.webp | B13: не уверен | C13: leto-shardone-2023-suhoe-beloe | D13: LETO Шардоне 2023 сухое белое — LETO — Белое сухое | E13: есть такое, но на фото черная этикетка вместо белой | F13: vinodelnya-uzunov-shardone-rezerv-beloe-suhoe-135 | G13: vinodelnya-konstantina-dzitoeva-kd-shardone-beloe-suhoe-128 | H13: vinodelnya-uzunov-rash-rezerv-risling-reynskiy-beloe-suhoe-127 | I13: shardone-rezerv | J13: vinodelnya-myshako-shardone-avtorskaya-tehnologiya-beloe-suhoe-155 | K13: =IF(C13="","",IFERROR(MATCH(C13,F13:J13,0),"нет")) | L13: =IF(C13="","",IF(K13=1,1,0)) | M13: =IF(C13="","",IF(ISNUMBER(K13),1,0)) | N13: Шардоне Резерв — Винодельня Узунов — Белое сухое | O13: KD Шардоне — Винодельня Константина Дзитоева — Белое сухое | P13: РАШ Резерв — Винодельня Узунов — Белое сухое | Q13: Шардоне Резерв — Усадьба Перовских — Белое сухое | R13: Шардоне авторская технология — Мысхако — Белое сухое
A14: 87.81_09-09-2026_17-16-36.webp | B14: не уверен | C14: aya-organic-wine-vineyards-purity-in-chenin-blanc-shenen-blan-beloe-suhoe-11 | D14: Purity in Chenin Blanc — AYA Organic Wine & Vineyards — Белое сухое | E14: есть похожее, но в названии вместо in balance написано in-chenin-blanc | F14: aya-organic-wine-vineyards-purity-in-syrah-sira-rozovoe-suhoe-132 | G14: aya-organic-wine-vineyards-purity-in-trinity-pino-nuar-rozovoe-suhoe-13 | H14: aya-organic-wine-vineyards-purity-in-syrah-sira-krasnoe-suhoe-146 | I14: aya-organic-wine-vineyards-purity-in-merlot-merlo-rozovoe-suhoe-134 | J14: aya-organic-wine-vineyards-purity-in-chenin-blanc-shenen-blan-beloe-suhoe-11 | K14: =IF(C14="","",IFERROR(MATCH(C14,F14:J14,0),"нет")) | L14: =IF(C14="","",IF(K14=1,1,0)) | M14: =IF(C14="","",IF(ISNUMBER(K14),1,0)) | N14: Purity in Syrah — AYA Organic Wine & Vineyards — Розовое сухое | O14: Purity in Trinity — AYA Organic Wine & Vineyards — Розовое сухое | P14: Purity in Syrah — AYA Organic Wine & Vineyards — Красное сухое | Q14: Purity in Merlot — AYA Organic Wine & Vineyards — Розовое сухое | R14: Purity in Chenin Blanc — AYA Organic Wine & Vineyards — Белое сухое
A15: 87.88_28-08-2026_16-56-20.webp | B15: не уверен | C15: massandra-muskatel-belyy-belye-sorta-vinograda-beloe-sladkoe-16 | D15: Мускатель белый — Массандра — Белое сладкое | E15: есть такое, но год урожая отличается | F15: massandra-muskatel-belyy-belye-sorta-vinograda-beloe-sladkoe-16 | G15: massandra-muskat-belyy-krasnogo-kamnya-beloe-sladkoe-13 | H15: massandra-muskatel-rozovyy-belye-sorta-vinograda-rozovoe-sladkoe-16 | I15: massandra-muskatel-chernyy-krasnye-sorta-vinograda-krasnoe-sladkoe-16 | J15: massandra-muskat-belyy-yuzhnoberezhnyy-beloe-sladkoe-16 | K15: =IF(C15="","",IFERROR(MATCH(C15,F15:J15,0),"нет")) | L15: =IF(C15="","",IF(K15=1,1,0)) | M15: =IF(C15="","",IF(ISNUMBER(K15),1,0)) | N15: Мускатель белый — Массандра — Белое сладкое | O15: Мускат белый красного камня — Массандра — Белое сладкое | P15: Мускатель розовый — Массандра — Розовое сладкое | Q15: Мускатель черный — Массандра — Красное сладкое | R15: Мускат Белый Южнобережный — Массандра — Белое сладкое
A16: 88.2_05-09-2026_16-29-06.webp | B16: нет в каталоге | F16: inkerman-shato-ruzh | G16: vinodelnya-begildeeva-kaberne-sovinon-krasnoe-suhoe-14 | H16: inkermanskiy-zmv-winemakers-selection-saperavi-krasnoe-polusladkoe-12 | I16: kuban-vino-kaberne-de-tamane-kaberne-sovinon-krasnoe-suhoe-125 | J16: inkerman-shato-blan | K16: =IF(C16="","",IFERROR(MATCH(C16,F16:J16,0),"нет")) | L16: =IF(C16="","",IF(K16=1,1,0)) | M16: =IF(C16="","",IF(ISNUMBER(K16),1,0)) | N16: Inkerman Шато Руж — Инкерманский ЗМВ — Красное полусухое | O16: Каберне Совиньон — Винодельня Бегильдеева — Красное сухое | P16: Winemaker's Selection Саперави — Инкерманский ЗМВ — Красное полусладкое | Q16: Каберне де Тамань — Кубань-Вино — Красное сухое | R16: Инкерман Шато Блан — Инкерманский ЗМВ — Белое полусухое
A17: 88.38_20-08-2026_18-32-58.webp | B17: уверенно | C17: czitronnyj-magaracha-sovinon-blan | D17: Жемчужная 9 Цитрон, Совиньон блан — АРАТТИ — Белое полусухое | F17: czitronnyj-magaracha-sovinon-blan | G17: zhemchuzhnaya-9-risling-sovinon-blan | H17: zhemchuzhnaya-9-aligote-czitron | I17: zhemchuzhnaya-9-czitron-shardone | J17: zhemchuzhnaya-9-czitron-shardone-1 | K17: =IF(C17="","",IFERROR(MATCH(C17,F17:J17,0),"нет")) | L17: =IF(C17="","",IF(K17=1,1,0)) | M17: =IF(C17="","",IF(ISNUMBER(K17),1,0)) | N17: Жемчужная 9 Цитрон, Совиньон блан — АРАТТИ — Белое полусухое | O17: Жемчужная 9 Рислинг,Совиньон блан — АРАТТИ — Белое полусухое | P17: Жемчужная 9 Алиготе, Цитрон — АРАТТИ — Белое сухое | Q17: Жемчужная 9 Цитрон, Шардоне — АРАТТИ — Белое сухое | R17: Жемчужная 9 Цитрон, Шардоне — АРАТТИ — Белое полусладкое
A18: 89.65_19-08-2026_19-48-39.webp | B18: уверенно | C18: rozovoe-zoloto | D18: Розовое золото — Табия — Розовое полусухое | F18: rozovoe-zoloto | G18: roze-2 | H18: bukovinka | I18: rozovaya-pantera | J18: rubin-golodrigi | K18: =IF(C18="","",IFERROR(MATCH(C18,F18:J18,0),"нет")) | L18: =IF(C18="","",IF(K18=1,1,0)) | M18: =IF(C18="","",IF(ISNUMBER(K18),1,0)) | N18: Розовое золото — Табия — Розовое полусухое | O18: Розе — Табия — Розовое сухое | P18: Буковинка — Табия — Белое полусухое | Q18: Розовая Пантера полусладкое розовое — АРАТТИ — Розовое полусладкое | R18: Рубин Голодриги — Табия — Красное сухое
A19: 90.5_02-09-2026_10-32-11.webp | B19: нет в каталоге | F19: inkerman-shato-ruzh | G19: inkerman-shato-blan | H19: inkerman-muskatnoe-beloe | I19: inkermanskiy-zmv-inkerman-polusladkoe-roze-aligote-rozovoe-135 | J19: inkermanskiy-zmv-inkerman-rozovoe-polusladkoe-rkatsiteli-12 | K19: =IF(C19="","",IFERROR(MATCH(C19,F19:J19,0),"нет")) | L19: =IF(C19="","",IF(K19=1,1,0)) | M19: =IF(C19="","",IF(ISNUMBER(K19),1,0)) | N19: Inkerman Шато Руж — Инкерманский ЗМВ — Красное полусухое | O19: Инкерман Шато Блан — Инкерманский ЗМВ — Белое полусухое | P19: Inkerman Мускатное белое — Инкерманский ЗМВ — Белое полусладкое | Q19: Inkerman полусладкое розе — Инкерманский ЗМВ — Розовое полусладкое | R19: Инкерман Розовое полусладкое — Инкерманский ЗМВ — Розовое полусладкое
A20: 91.07_20-08-2026_18-37-46.webp | B20: уверенно | C20: aratti-kaberne-sovinon-2021-krasnoe-suhoe | D20: АРАТТИ Каберне Совиньон 2021 красное сухое — АРАТТИ — Красное сухое | F20: aratti-kaberne-sovinon-2021-krasnoe-suhoe | G20: aratti-kaberne-sovinon-2020-krasnoe-suhoe | H20: aratti-kaberne-po-belomu | I20: aratti-kaberne-po-belomu-1 | J20: aratti-sovinon-blan-beloe-polusuhoe | K20: =IF(C20="","",IFERROR(MATCH(C20,F20:J20,0),"нет")) | L20: =IF(C20="","",IF(K20=1,1,0)) | M20: =IF(C20="","",IF(ISNUMBER(K20),1,0)) | N20: АРАТТИ Каберне Совиньон 2021 красное сухое — АРАТТИ — Красное сухое | O20: АРАТТИ Каберне Совиньон 2020 красное сухое — АРАТТИ — Красное сухое | P20: АРАТТИ Каберне по-белому — АРАТТИ — Красное сухое | Q20: АРАТТИ Каберне по-белому — АРАТТИ — Розовое полусухое | R20: АРАТТИ Совиньон блан белое полусухое — АРАТТИ — Белое полусухое
A21: 91.43_02-09-2026_12-08-50.webp | B21: уверенно | C21: merlo-2 | D21: Мерло — Литавщук. Litavshchuk vineyards & winery — Красное сухое | F21: merlo-2 | G21: vinodelnya-begildeeva-merlo-krasnoe-suhoe-14 | H21: vinodelnya-begildeeva-kaberne-sovinon-merlo-krasnoe-suhoe-14 | I21: merlo | J21: vinnyy-kooperativ-intuitsiya-kaberne-sovinon-merlo-saperavi-krasnoe-suhoe-128 | K21: =IF(C21="","",IFERROR(MATCH(C21,F21:J21,0),"нет")) | L21: =IF(C21="","",IF(K21=1,1,0)) | M21: =IF(C21="","",IF(ISNUMBER(K21),1,0)) | N21: Мерло — Литавщук. Litavshchuk vineyards & winery — Красное сухое | O21: Мерло — Винодельня Бегильдеева — Красное сухое | P21: Каберне Совиньон – Мерло — Винодельня Бегильдеева — Красное сухое | Q21: Мерло — Галицкий и Галицкий — Красное сухое | R21: Каберне Совиньон - Мерло — Винный кооператив Интуиция — Красное сухое
